Workbook

Sheet Raw Data
A1: Project_ID | B1: Project_Name | C1: Phase | D1: Contractor | E1: Material_Cost_EUR | F1: Labor_Cost_EUR | G1: Planned_Start | H1: Actual_Start | I1: Planned_End | J1: Actual_End | K1: Budget_EUR | L1: Status | M1: Notes
A2: P1000 | B2: Mitte Office Tower | C2: foundation | D2: STRABAG SE | E2: 58753.76 | F2: 76754.98 | G2: 16.01.2023 | H2: 2023-02-01 | I2: 31/03/2023 | J2: 03/26/2023 | K2: 124256.53 | L2: On Hold
A3: P1025 | B3: Friedrichshain Loft | C3: Structure | D3: Max Bögl | E3: 142965.08 | F3: 52249.31 | G3: 23.03.2023 | H3: 2023-03-28 | I3: 06/05/2023 | J3: 04/26/2023 | K3: 203735.54 | L3: ON HOLD
A4: P1010 | B4: Prenzlauer Berg Retail | C4: Finishing | D4: Bilfinger SE | E4: 137994.94 | F4: 124048.4 | G4: 25.05.2023 | H4: 2023-06-12 | I4: 11/07/2023 | J4: 08/04/2023 | K4: 296824.16 | L4: delayed
A5: P1005 | B5: Kreuzberg Residential | C5: Structure | D5: Züblin AG | E5: 179563.34 | F5: 65616.2 | G5: 26.03.2023 | H5: 2023-04-10 | I5: 09/05/2023 | J5: 06/06/2023 | K5: 228039.86 | L5: COMPLETED | M5: Check invoice
A6: P1007 | B6: Kreuzberg Residential | C6: mep | D6: Goldbeck GmbH | E6: 73166.01 | F6: 185233.14 | G6: 19.07.2023 | H6: 2023-07-20 | I6: 28/09/2023 | J6: 10/13/2023 | K6: 263606.93 | L6: on hold
A7: P1014 | B7: Charlottenburg Hotel | C7: Finishing | D7: Bilfinger SE | E7: 107794.44 | F7: 119704.54 | G7: 18.05.2023 | H7: 2023-05-30 | I7: 09/07/2023 | J7: 07/18/2023 | K7: 234773.98 | L7: ON HOLD | M7: Material delay
A8: P1003 | B8: Mitte Office Tower | C8: Mep | D8: Hochtief AG | E8: 346623.03 | F8: 132633.43 | G8: 21.07.2023 | H8: 2023-08-02 | I8: 06/09/2023 | J8: 09/20/2023 | K8: 523414.42 | L8: in progress | M8: Material delay
A9: P1021 | B9: Spandau Logistics Hub | C9: Structure | D9: Ed. Züblin | E9: 365855 | F9: 57988.31 | G9: 22.03.2023 | H9: 2023-03-25 | I9: 30/05/2023 | J9: 06/07/2023 | K9: 360540.88 | L9: ON HOLD | M9: TBC
A10: P1031 | B10: Wedding School Extension | C10: MEP | D10: Goldbeck GmbH | E10: 177628.03 | F10: 188624.96 | G10: 14.07.2023 | H10: 2023-07-20 | I10: 05/09/2023 | J10: 09/10/2023 | K10: 418135.98 | L10: IN PROGRESS | M10: N/A
A11: P1038 | B11: Lichtenberg Warehouse | C11: FINISHING | D11: Porr GmbH | E11: 159870.48 | F11: 174162.6 | G11: 19.05.2023 | H11: 2023-05-30 | I11: 17/07/2023 | J11: 08/02/2023 | K11: 356054.64 | L11: DELAYED | M11: Pending approval
A12: P1000 | B12: Mitte Office Tower | C12: foundation | D12: STRABAG SE | E12: 58753.76 | F12: 76754.98 | G12: 16.01.2023 | H12: 2023-02-01 | I12: 31/03/2023 | J12: 03/26/2023 | K12: 124256.53 | L12: On Hold
A13: P1016 | B13: Neukölln Mixed-Use | C13: FOUNDATION | D13: STRABAG SE | E13: 297744.33 | F13: 40008.54 | G13: 15.01.2023 | H13: 2023-01-20 | I13: 28/02/2023 | J13: 03/22/2023 | K13: 293919.34 | L13: COMPLETED | M13: n/a
A14: P1013 | B14: Charlottenburg Hotel | C14: structure | D14: Goldbeck GmbH | E14: 133808.31 | F14: 70948.17 | G14: 17.03.2023 | H14: 2023-03-14 | I14: 27/05/2023 | J14: 05/21/2023 | K14: 208894.01 | L14: COMPLETED | M14: n/a
A15: P1011 | B15: Prenzlauer Berg Retail | C15: Mep | D15: Goldbeck GmbH | E15: 202167.84 | F15: 107133.03 | G15: 18.07.2023 | H15: 2023-07-29 | I15: 07/09/2023 | J15: 09/29/2023 | K15: 351410.57 | L15: in progress | M15: TBC
A16: P1002 | B16: Mitte Office Tower | C16: finishing | D16: Bauer GmbH | E16: 315582.58 | F16: 57142.08 | G16: 19.05.2023 | H16: 2023-05-18 | I16: 11/07/2023 | J16: 07/22/2023 | K16: 364071.6 | L16: in progress
A17: P1036 | B17: Lichtenberg Warehouse | C17: FOUNDATION | D17: Bauer GmbH | E17: 87940.89 | F17: 103875.84 | G17: 20.01.2023 | H17: 2023-01-28 | I17: 08/04/2023 | J17: 04/30/2023 | K17: 204968.36 | L17: IN PROGRESS | M17: Check invoice
A18: P1006 | B18: Kreuzberg Residential | C18: finishing | D18: Züblin AG | E18: 211791.07 | F18: 75891.13 | G18: 23.05.2023 | H18: 2023-05-25 | I18: 22/07/2023 | J18: 07/15/2023 | K18: 324395.44 | L18: completed | M18: N/A
A19: P1023 | B19: Spandau Logistics Hub | C19: Mep | D19: Bilfinger SE | E19: 371785.5 | F19: 120291.44 | G19: 22.07.2023 | H19: 2023-07-19 | I19: 11/09/2023 | J19: 09/05/2023 | K19: 426662.14 | L19: In Progress | M19: N/A
A20: P1009 | B20: Prenzlauer Berg Retail | C20: STRUCTURE | D20: STRABAG SE | E20: 314523.76 | F20: 176387.49 | G20: 18.03.2023 | H20: 2023-04-07 | I20: 24/05/2023 | J20: 06/21/2023 | K20: 439784.02 | L20: in progress | M20: n/a
A21: P1039 | B21: Lichtenberg Warehouse | C21: MEP | D21: Bilfinger SE | E21: 94550.73 | F21: 101475.88 | G21: 24.07.2023 | H21: 2023-08-11 | I21: 13/09/2023 | J21: 10/12/2023 | K21: 221923.51 | L21: DELAYED
A22: P1035 | B22: Steglitz Medical Centre | C22: mep | D22: Hochtief AG | E22: 274518.61 | F22: 97945.33 | G22: 22.07.2023 | H22: 2023-07-27 | I22: 01/09/2023 | J22: 08/29/2023 | K22: 426227.21 | L22: DELAYED | M22: Pending approval
A23: P1034 | B23: Steglitz Medical Centre | C23: FINISHING | D23: Implenia DE | E23: 172380.45 | F23: 169491.18 | G23: 18.05.2023 | H23: 2023-05-13 | I23: 09/07/2023 | J23: 07/24/2023 | K23: 379955.07 | L23: Delayed | M23: Pending approval
A24: P1015 | B24: Charlottenburg Hotel | C24: Mep | D24: Implenia DE | E24: 364864.93 | F24: 106752.64 | G24: 15.07.2023 | H24: 2023-07-20 | I24: 25/08/2023 | J24: 09/21/2023 | K24: 435949.93 | L24: Completed
A25: P1008 | B25: Prenzlauer Berg Retail | C25: foundation | D25: Max Bögl | E25: 310746.14 | F25: 121626.14 | G25: 21.01.2023 | H25: 2023-02-03 | I25: 27/03/2023 | J25: 04/09/2023 | K25: 464412.86 | L25: COMPLETED | M25: n/a
A26: P1001 | B26: Mitte Office Tower | C26: STRUCTURE | D26: Max Bögl | E26: 131431.31 | F26: 132343.18 | G26: 26.03.2023 | H26: 2023-04-12 | I26: 08/06/2023 | J26: 06/24/2023 | K26: 268620.96 | L26: COMPLETED | M26: Pending approval
A27: P1020 | B27: Spandau Logistics Hub | C27: FOUNDATION | D27: Bauer GmbH | E27: 278250.71 | F27: 121899.95 | G27: 16.01.2023 | H27: 2023-02-04 | I27: 12/03/2023 | J27: 03/12/2023 | K27: 341899.67 | L27: on hold | M27: Check invoice
A28: P1004 | B28: Kreuzberg Residential | C28: FOUNDATION | D28: Porr GmbH | E28: 117301.01 | F28: 41824.38 | G28: 19.01.2023 | H28: 2023-01-16 | I28: 14/03/2023 | J28: 03/10/2023 | K28: 166823.72 | L28: on hold | M28: Material delay
A29: P1022 | B29: Spandau Logistics Hub | C29: finishing | D29: Implenia DE | E29: 104178.89 | F29: 80440.33 | G29: 24.05.2023 | H29: 2023-06-11 | I29: 06/08/2023 | J29: 07/30/2023 | K29: 210579.05 | L29: Delayed | M29: n/a
A30: P1030 | B30: Wedding School Extension | C30: FINISHING | D30: Bilfinger SE | E30: 296983.61 | F30: 125354.17 | G30: 17.05.2023 | H30: 2023-05-29 | I30: 28/06/2023 | J30: 07/11/2023 | K30: 373161.68 | L30: Completed
A31: P1032 | B31: Steglitz Medical Centre | C31: foundation | D31: Porr GmbH | E31: 312317.16 | F31: 187379.85 | G31: 17.01.2023 | H31: 2023-02-06 | I31: 09/03/2023 | J31: 03/25/2023 | K31: 460231.54 | L31: IN PROGRESS | M31: Material delay
A32: P1024 | B32: Friedrichshain Loft | C32: FOUNDATION | D32: STRABAG SE | E32: 379558.64 | F32: 126844.82 | G32: 15.01.2023 | H32: 2023-01-29 | I32: 01/03/2023 | J32: 03/17/2023 | K32: 518392.93 | L32: Delayed | M32: Material delay
A33: P1029 | B33: Wedding School Extension | C33: structure | D33: Bauer GmbH | E33: 82304.46 | F33: 102007.88 | G33: 16.03.2023 | H33: 2023-03-21 | I33: 03/05/2023 | J33: 06/02/2023 | K33: 171964.16 | L33: DELAYED | M33: n/a
A34: P1037 | B34: Lichtenberg Warehouse | C34: structure | D34: Goldbeck GmbH | E34: 65535.29 | F34: 104129.78 | G34: 24.03.2023 | H34: 2023-04-09 | I34: 15/05/2023 | J34: 05/28/2023 | K34: 170679.01 | L34: ON HOLD | M34: Material delay
A35: P1033 | B35: Steglitz Medical Centre | C35: STRUCTURE | D35: Ed. Züblin | E35: 330782.3 | F35: 176890.88 | G35: 20.03.2023 | H35: 2023-03-20 | I35: 05/05/2023 | J35: 05/19/2023 | K35: 555000.91 | L35: In Progress | M35: Check invoice
A36: P1027 | B36: Friedrichshain Loft | C36: mep | D36: Goldbeck GmbH | E36: 264087.22 | F36: 197829.62 | G36: 14.07.2023 | H36: 2023-07-30 | I36: 27/09/2023 | J36: 10/06/2023 | K36: 483254.12 | L36: in progress
A37: P1028 | B37: Wedding School Extension | C37: Foundation | D37: STRABAG SE | E37: 309845.84 | F37: 56426.14 | G37: 18.01.2023 | H37: 2023-02-04 | I37: 20/03/2023 | J37: 03/23/2023 | K37: 342291.01 | L37: delayed | M37: Pending approval
A38: P1019 | B38: Neukölln Mixed-Use | C38: MEP | D38: Max Bögl | E38: 117056.53 | F38: 121168.58 | G38: 16.07.2023 | H38: 2023-07-19 | I38: 23/09/2023 | J38: 09/28/2023 | K38: 212509.83 | L38: IN PROGRESS
A39: P1026 | B39: Friedrichshain Loft | C39: finishing | D39: STRABAG SE | E39: 238172.04 | F39: 116000.4 | G39: 20.05.2023 | H39: 2023-05-17 | I39: 14/07/2023 | J39: 07/27/2023 | K39: 315120.31 | L39: delayed | M39: TBC
A40: P1012 | B40: Charlottenburg Hotel | C40: foundation | D40: Porr GmbH | E40: 119618.89 | F40: 93565.35 | G40: 23.01.2023 | H40: 2023-01-18 | I40: 11/04/2023 | J40: 04/21/2023 | K40: 191538.52 | L40: On Hold | M40: Material delay
...

Sheet 2_Contractor_Rates
A1: Contractor_Name | B1: Daily_Rate_EUR | C1: Overhead_% | D1: Specialization | E1: Risk_Rating | F1: Region
A2: Bauer GmbH | B2: 1850 | C2: 0.12 | D2: Geotechnical | E2: Low | F2: Berlin
A3: STRABAG SE | B3: 2200 | C3: 0.15 | D3: General Civil | E3: Low | F3: National
A4: Züblin AG | B4: 2100 | C4: 0.14 | D4: Structural | E4: Low | F4: National
A5: Max Bögl | B5: 1950 | C5: 0.13 | D5: Precast | E5: Medium | F5: Bavaria
A6: Goldbeck GmbH | B6: 1800 | C6: 0.11 | D6: Commercial | E6: Low | F6: National
A7: Hochtief AG | B7: 2400 | C7: 0.16 | D7: Large Scale | E7: Low | F7: International
A8: Ed. Züblin | B8: 2050 | C8: 0.14 | D8: Structural | E8: Medium | F8: National
A9: Implenia DE | B9: 1900 | C9: 0.12 | D9: Mixed-Use | E9: Low | F9: National
A10: Bilfinger SE | B10: 2150 | C10: 0.15 | D10: Industrial | E10: Medium | F10: National
A11: Porr GmbH | B11: 1750 | C11: 0.11 | D11: Residential | E11: Low | F11: Berlin

Sheet 3_Cleaned_Data
A1: Project _ID | B1: Project_Name | C1: Phase | D1: Contractor | E1: Material_Cost_EUR | F1: Labour_Cost_EUR | G1: Planned _Start | H1: Actual_start | I1: Planned_End | J1: Actual_End | K1: Budget_EUR | L1: Actual_Cost_EUR | M1: Variance_EUR | N1: Variance_% | O1: Status | P1: Contractor_Daily_Rate | Q1: Overhead_% | R1: Days_Delay
A2: P1000 | B2: Mitte Office Tower | C2: Foundation | D2: STRABAG SE | E2: 58753.76 | F2: 76754.98 | G2: 16.01.2023 | H2: 44958 | I2: 45016 | J2: 45011 | K2: 124256.53 | L2: =E2+F2 -> 135508.74 | M2: =L2-K2 -> 11252.21 | N2: =M2/K2 -> 0.090556287 | O2: On Hold | P2: =VLOOKUP('3_Cleaned_Data'!D2,'2_Contractor_Rates'!$A:$B,2,0) -> 2200 | Q2: =INDEX('2_Contractor_Rates'!$C:$C,MATCH(D2,'2_Contractor_Rates'!$A:$A,0)) -> 0.15 | R2: =J2-I2 -> -5
A3: P1025 | B3: Friedrichshain Loft | C3: Structure | D3: Max Bögl | E3: 142965.08 | F3: 52249.31 | G3: 23.03.2023 | H3: 45013 | I3: 45052 | J3: 45042 | K3: 203735.54 | L3: =E3+F3 -> 195214.39 | M3: =L3-K3 -> -8521.15 | N3: =M3/K3 -> -0.041824563 | O3: On Hold | P3: =VLOOKUP('3_Cleaned_Data'!D3,'2_Contractor_Rates'!$A:$B,2,0) -> 1950 | Q3: =INDEX('2_Contractor_Rates'!$C:$C,MATCH(D3,'2_Contractor_Rates'!$A:$A,0)) -> 0.13 | R3: =J3-I3 -> -10
A4: P1010 | B4: Prenzlauer Berg Retail | C4: Finishing | D4: Bilfinger SE | E4: 137994.94 | F4: 124048.4 | G4: 25.05.2023 | H4: 45089 | I4: 45118 | J4: 45142 | K4: 296824.16 | L4: =E4+F4 -> 262043.34 | M4: =L4-K4 -> -34780.82 | N4: =M4/K4 -> -0.11717651 | O4: Delayed | P4: =VLOOKUP('3_Cleaned_Data'!D4,'2_Contractor_Rates'!$A:$B,2,0) -> 2150 | Q4: =INDEX('2_Contractor_Rates'!$C:$C,MATCH(D4,'2_Contractor_Rates'!$A:$A,0)) -> 0.15 | R4: =J4-I4 -> 24
A5: P1005 | B5: Kreuzberg Residential | C5: Structure | D5: Züblin AG | E5: 179563.34 | F5: 65616.2 | G5: 26.03.2023 | H5: 45026 | I5: 45055 | J5: 45083 | K5: 228039.86 | L5: =E5+F5 -> 245179.54 | M5: =L5-K5 -> 17139.68 | N5: =M5/K5 -> 0.075160895 | O5: Completed | P5: =VLOOKUP('3_Cleaned_Data'!D5,'2_Contractor_Rates'!$A:$B,2,0) -> 2100 | Q5: =INDEX('2_Contractor_Rates'!$C:$C,MATCH(D5,'2_Contractor_Rates'!$A:$A,0)) -> 0.14 | R5: =J5-I5 -> 28
A6: P1007 | B6: Kreuzberg Residential | C6: Mep | D6: Goldbeck GmbH | E6: 73166.01 | F6: 185233.14 | G6: 19.07.2023 | H6: 45127 | I6: 45197 | J6: 45212 | K6: 263606.93 | L6: =E6+F6 -> 258399.15 | M6: =L6-K6 -> -5207.78 | N6: =M6/K6 -> -0.019755854 | O6: On Hold | P6: =VLOOKUP('3_Cleaned_Data'!D6,'2_Contractor_Rates'!$A:$B,2,0) -> 1800 | Q6: =INDEX('2_Contractor_Rates'!$C:$C,MATCH(D6,'2_Contractor_Rates'!$A:$A,0)) -> 0.11 | R6: =J6-I6 -> 15
A7: P1014 | B7: Charlottenburg Hotel | C7: Finishing | D7: Bilfinger SE | E7: 107794.44 | F7: 119704.54 | G7: 18.05.2023 | H7: 45076 | I7: 45116 | J7: 45125 | K7: 234773.98 | L7: =E7+F7 -> 227498.98 | M7: =L7-K7 -> -7275 | N7: =M7/K7 -> -0.03098725 | O7: On Hold | P7: =VLOOKUP('3_Cleaned_Data'!D7,'2_Contractor_Rates'!$A:$B,2,0) -> 2150 | Q7: =INDEX('2_Contractor_Rates'!$C:$C,MATCH(D7,'2_Contractor_Rates'!$A:$A,0)) -> 0.15 | R7: =J7-I7 -> 9
A8: P1003 | B8: Mitte Office Tower | C8: Mep | D8: Hochtief AG | E8: 346623.03 | F8: 132633.43 | G8: 21.07.2023 | H8: 45140 | I8: 45175 | J8: 45189 | K8: 523414.42 | L8: =E8+F8 -> 479256.46 | M8: =L8-K8 -> -44157.96 | N8: =M8/K8 -> -0.084365196 | O8: In Progress | P8: =VLOOKUP('3_Cleaned_Data'!D8,'2_Contractor_Rates'!$A:$B,2,0) -> 2400 | Q8: =INDEX('2_Contractor_Rates'!$C:$C,MATCH(D8,'2_Contractor_Rates'!$A:$A,0)) -> 0.16 | R8: =J8-I8 -> 14
A9: P1021 | B9: Spandau Logistics Hub | C9: Structure | D9: Ed. Züblin | E9: 365855 | F9: 57988.31 | G9: 22.03.2023 | H9: 45010 | I9: 45076 | J9: 45084 | K9: 360540.88 | L9: =E9+F9 -> 423843.31 | M9: =L9-K9 -> 63302.43 | N9: =M9/K9 -> 0.17557629 | O9: On Hold | P9: =VLOOKUP('3_Cleaned_Data'!D9,'2_Contractor_Rates'!$A:$B,2,0) -> 2050 | Q9: =INDEX('2_Contractor_Rates'!$C:$C,MATCH(D9,'2_Contractor_Rates'!$A:$A,0)) -> 0.14 | R9: =J9-I9 -> 8
A10: P1031 | B10: Wedding School Extension | C10: Mep | D10: Goldbeck GmbH | E10: 177628.03 | F10: 188624.96 | G10: 14.07.2023 | H10: 45127 | I10: 45174 | J10: 45179 | K10: 418135.98 | L10: =E10+F10 -> 366252.99 | M10: =L10-K10 -> -51882.99 | N10: =M10/K10 -> -0.12408162 | O10: In Progress | P10: =VLOOKUP('3_Cleaned_Data'!D10,'2_Contractor_Rates'!$A:$B,2,0) -> 1800 | Q10: =INDEX('2_Contractor_Rates'!$C:$C,MATCH(D10,'2_Contractor_Rates'!$A:$A,0)) -> 0.11 | R10: =J10-I10 -> 5
A11: P1038 | B11: Lichtenberg Warehouse | C11: Finishing | D11: Porr GmbH | E11: 159870.48 | F11: 174162.6 | G11: 19.05.2023 | H11: 45076 | I11: 45124 | J11: 45140 | K11: 356054.64 | L11: =E11+F11 -> 334033.08 | M11: =L11-K11 -> -22021.56 | N11: =M11/K11 -> -0.061848822 | O11: Delayed | P11: =VLOOKUP('3_Cleaned_Data'!D11,'2_Contractor_Rates'!$A:$B,2,0) -> 1750 | Q11: =INDEX('2_Contractor_Rates'!$C:$C,MATCH(D11,'2_Contractor_Rates'!$A:$A,0)) -> 0.11 | R11: =J11-I11 -> 16
A12: P1016 | B12: Neukölln Mixed-Use | C12: Foundation | D12: STRABAG SE | E12: 297744.33 | F12: 40008.54 | G12: 15.01.2023 | H12: 44946 | I12: 44985 | J12: 45007 | K12: 293919.34 | L12: =E12+F12 -> 337752.87 | M12: =L12-K12 -> 43833.53 | N12: =M12/K12 -> 0.14913456 | O12: Completed | P12: =VLOOKUP('3_Cleaned_Data'!D12,'2_Contractor_Rates'!$A:$B,2,0) -> 2200 | Q12: =INDEX('2_Contractor_Rates'!$C:$C,MATCH(D12,'2_Contractor_Rates'!$A:$A,0)) -> 0.15 | R12: =J12-I12 -> 22
A13: P1013 | B13: Charlottenburg Hotel | C13: Structure | D13: Goldbeck GmbH | E13: 133808.31 | F13: 70948.17 | G13: 17.03.2023 | H13: 44999 | I13: 45073 | J13: 45067 | K13: 208894.01 | L13: =E13+F13 -> 204756.48 | M13: =L13-K13 -> -4137.53 | N13: =M13/K13 -> -0.019806839 | O13: Completed | P13: =VLOOKUP('3_Cleaned_Data'!D13,'2_Contractor_Rates'!$A:$B,2,0) -> 1800 | Q13: =INDEX('2_Contractor_Rates'!$C:$C,MATCH(D13,'2_Contractor_Rates'!$A:$A,0)) -> 0.11 | R13: =J13-I13 -> -6
... A41: P1018 | B41: Neukölln Mixed-Use | C41: Finishing | D41: Ed. Züblin | E41: 174004.15 | F41: 99887.39 | G41: 15.05.2023 | H41: 45077 | I41: 45107 | J41: 45100 | K41: 303787.08 | L41: =E41+F41 -> 273891.54 | M41: =L41-K41 -> -29895.54 | N41: =M41/K41 -> -0.098409518 | O41: On Hold | P41: =VLOOKUP('3_Cleaned_Data'!D41,'2_Contractor_Rates'!$A:$B,2,0) -> 2050 | Q41: =INDEX('2_Contractor_Rates'!$C:$C,MATCH(D41,'2_Contractor_Rates'!$A:$A,0)) -> 0.14 | R41: =J41-I41 -> -7

Sheet 4_Pivot_Analysis
A1: phase | B1: Budget | C1: Actual Cost | D1: Variance | E1: Variance % | F1: Status
A2: Foundation | B2: =SUMIF('3_Cleaned_Data'!$C:$C,A2,'3_Cleaned_Data'!$K:$K) -> 3321244.3 | C2: =SUMIF('3_Cleaned_Data'!$C:$C,A2,'3_Cleaned_Data'!$L:$L) -> 3480508.5 | D2: =C2-B2 -> 159264.16 | E2: =D2/B2 -> 0.04795316 | F2: =IF(E2>0.1,"Over Budget",IF(E2>0,"Watch","On Track")) -> Watch
A3: Structure | B3: =SUMIF('3_Cleaned_Data'!$C:$C,A3,'3_Cleaned_Data'!$K:$K) -> 3043895.2 | C3: =SUMIF('3_Cleaned_Data'!$C:$C,A3,'3_Cleaned_Data'!$L:$L) -> 3077031.9 | D3: =C3-B3 -> 33136.66 | E3: =D3/B3 -> 0.010886268 | F3: =IF(E3>0.1,"Over Budget",IF(E3>0,"Watch","On Track")) -> Watch
A4: Finishing | B4: =SUMIF('3_Cleaned_Data'!$C:$C,A4,'3_Cleaned_Data'!$K:$K) -> 3158723 | C4: =SUMIF('3_Cleaned_Data'!$C:$C,A4,'3_Cleaned_Data'!$L:$L) -> 3060874.9 | D4: =C4-B4 -> -97848.14 | E4: =D4/B4 -> -0.030977119 | F4: =IF(E4>0.1,"Over Budget",IF(E4>0,"Watch","On Track")) -> On Track
A5: Mep | B5: =SUMIF('3_Cleaned_Data'!$C:$C,A5,'3_Cleaned_Data'!$K:$K) -> 3550584.8 | C5: =SUMIF('3_Cleaned_Data'!$C:$C,A5,'3_Cleaned_Data'!$L:$L) -> 3407311.4 | D5: =C5-B5 -> -143273.44 | E5: =D5/B5 -> -0.040352068 | F5: =IF(E5>0.1,"Over Budget",IF(E5>0,"Watch","On Track")) -> On Track
A6: Total | B6: =SUM(B2:B5) -> 13074447 | C6: =SUM(C2:C5) -> 13025727 | D6: =SUM(D2:D5) -> -48720.76 | E6: =D6/B6 -> -0.0037264107 | F6: =IF(E6>0.1,"Over Budget",IF(E6>0,"Watch","On Track")) -> On Track
A9: Project Name | B9: Foundation | C9: Structure | D9: Finishing | E9: Mep | F9: Grand Total
A10: Mitte Office Tower | B10: =SUMIFS('3_Cleaned_Data'!$L:$L,'3_Cleaned_Data'!$B:$B,$A10,'3_Cleaned_Data'!$C:$C,B$9) -> 135508.74 | C10: =SUMIFS('3_Cleaned_Data'!$L:$L,'3_Cleaned_Data'!$B:$B,$A10,'3_Cleaned_Data'!$C:$C,C$9) -> 263774.49 | D10: =SUMIFS('3_Cleaned_Data'!$L:$L,'3_Cleaned_Data'!$B:$B,$A10,'3_Cleaned_Data'!$C:$C,D$9) -> 372724.66 | E10: =SUMIFS('3_Cleaned_Data'!$L:$L,'3_Cleaned_Data'!$B:$B,$A10,'3_Cleaned_Data'!$C:$C,E$9) -> 479256.46 | F10: =SUM(B10:E10) -> 1251264.4
A11: Kreuzberg Residential | B11: =SUMIFS('3_Cleaned_Data'!$L:$L,'3_Cleaned_Data'!$B:$B,$A11,'3_Cleaned_Data'!$C:$C,B$9) -> 159125.39 | C11: =SUMIFS('3_Cleaned_Data'!$L:$L,'3_Cleaned_Data'!$B:$B,$A11,'3_Cleaned_Data'!$C:$C,C$9) -> 245179.54 | D11: =SUMIFS('3_Cleaned_Data'!$L:$L,'3_Cleaned_Data'!$B:$B,$A11,'3_Cleaned_Data'!$C:$C,D$9) -> 287682.2 | E11: =SUMIFS('3_Cleaned_Data'!$L:$L,'3_Cleaned_Data'!$B:$B,$A11,'3_Cleaned_Data'!$C:$C,E$9) -> 258399.15 | F11: =SUM(B11:E11) -> 950386.28
A12: Prenzlauer Berg Retail | B12: =SUMIFS('3_Cleaned_Data'!$L:$L,'3_Cleaned_Data'!$B:$B,$A12,'3_Cleaned_Data'!$C:$C,B$9) -> 432372.28 | C12: =SUMIFS('3_Cleaned_Data'!$L:$L,'3_Cleaned_Data'!$B:$B,$A12,'3_Cleaned_Data'!$C:$C,C$9) -> 490911.25 | D12: =SUMIFS('3_Cleaned_Data'!$L:$L,'3_Cleaned_Data'!$B:$B,$A12,'3_Cleaned_Data'!$C:$C,D$9) -> 262043.34 | E12: =SUMIFS('3_Cleaned_Data'!$L:$L,'3_Cleaned_Data'!$B:$B,$A12,'3_Cleaned_Data'!$C:$C,E$9) -> 309300.87 | F12: =SUM(B12:E12) -> 1494627.7
A13: Charlottenburg Hotel | B13: =SUMIFS('3_Cleaned_Data'!$L:$L,'3_Cleaned_Data'!$B:$B,$A13,'3_Cleaned_Data'!$C:$C,B$9) -> 213184.24 | C13: =SUMIFS('3_Cleaned_Data'!$L:$L,'3_Cleaned_Data'!$B:$B,$A13,'3_Cleaned_Data'!$C:$C,C$9) -> 204756.48 | D13: =SUMIFS('3_Cleaned_Data'!$L:$L,'3_Cleaned_Data'!$B:$B,$A13,'3_Cleaned_Data'!$C:$C,D$9) -> 227498.98 | E13: =SUMIFS('3_Cleaned_Data'!$L:$L,'3_Cleaned_Data'!$B:$B,$A13,'3_Cleaned_Data'!$C:$C,E$9) -> 471617.57 | F13: =SUM(B13:E13) -> 1117057.3
A14: Neukölln Mixed-Use | B14: =SUMIFS('3_Cleaned_Data'!$L:$L,'3_Cleaned_Data'!$B:$B,$A14,'3_Cleaned_Data'!$C:$C,B$9) -> 575977.98 | C14: =SUMIFS('3_Cleaned_Data'!$L:$L,'3_Cleaned_Data'!$B:$B,$A14,'3_Cleaned_Data'!$C:$C,C$9) -> 391701.82 | D14: =SUMIFS('3_Cleaned_Data'!$L:$L,'3_Cleaned_Data'!$B:$B,$A14,'3_Cleaned_Data'!$C:$C,D$9) -> 273891.54 | E14: =SUMIFS('3_Cleaned_Data'!$L:$L,'3_Cleaned_Data'!$B:$B,$A14,'3_Cleaned_Data'!$C:$C,E$9) -> 0 | F14: =SUM(B14:E14) -> 1241571.3
A15: Spandau Logistics Hub | B15: =SUMIFS('3_Cleaned_Data'!$L:$L,'3_Cleaned_Data'!$B:$B,$A15,'3_Cleaned_Data'!$C:$C,B$9) -> 400150.66 | C15: =SUMIFS('3_Cleaned_Data'!$L:$L,'3_Cleaned_Data'!$B:$B,$A15,'3_Cleaned_Data'!$C:$C,C$9) -> 423843.31 | D15: =SUMIFS('3_Cleaned_Data'!$L:$L,'3_Cleaned_Data'!$B:$B,$A15,'3_Cleaned_Data'!$C:$C,D$9) -> 184619.22 | E15: =SUMIFS('3_Cleaned_Data'!$L:$L,'3_Cleaned_Data'!$B:$B,$A15,'3_Cleaned_Data'!$C:$C,E$9) -> 492076.94 | F15: =SUM(B15:E15) -> 1500690.1
A16: Friedrichshain Loft | B16: =SUMIFS('3_Cleaned_Data'!$L:$L,'3_Cleaned_Data'!$B:$B,$A16,'3_Cleaned_Data'!$C:$C,B$9) -> 506403.46 | C16: =SUMIFS('3_Cleaned_Data'!$L:$L,'3_Cleaned_Data'!$B:$B,$A16,'3_Cleaned_Data'!$C:$C,C$9) -> 195214.39 | D16: =SUMIFS('3_Cleaned_Data'!$L:$L,'3_Cleaned_Data'!$B:$B,$A16,'3_Cleaned_Data'!$C:$C,D$9) -> 354172.44 | E16: =SUMIFS('3_Cleaned_Data'!$L:$L,'3_Cleaned_Data'!$B:$B,$A16,'3_Cleaned_Data'!$C:$C,E$9) -> 461916.84 | F16: =SUM(B16:E16) -> 1517707.1
A17: Wedding School Extension | B17: =SUMIFS('3_Cleaned_Data'!$L:$L,'3_Cleaned_Data'!$B:$B,$A17,'3_Cleaned_Data'!$C:$C,B$9) -> 366271.98 | C17: =SUMIFS('3_Cleaned_Data'!$L:$L,'3_Cleaned_Data'!$B:$B,$A17,'3_Cleaned_Data'!$C:$C,C$9) -> 184312.34 | D17: =SUMIFS('3_Cleaned_Data'!$L:$L,'3_Cleaned_Data'!$B:$B,$A17,'3_Cleaned_Data'!$C:$C,D$9) -> 422337.78 | E17: =SUMIFS('3_Cleaned_Data'!$L:$L,'3_Cleaned_Data'!$B:$B,$A17,'3_Cleaned_Data'!$C:$C,E$9) -> 366252.99 | F17: =SUM(B17:E17) -> 1339175.1
A18: Steglitz Medical Centre | B18: =SUMIFS('3_Cleaned_Data'!$L:$L,'3_Cleaned_Data'!$B:$B,$A18,'3_Cleaned_Data'!$C:$C,B$9) -> 499697.01 | C18: =SUMIFS('3_Cleaned_Data'!$L:$L,'3_Cleaned_Data'!$B:$B,$A18,'3_Cleaned_Data'!$C:$C,C$9) -> 507673.18 | D18: =SUMIFS('3_Cleaned_Data'!$L:$L,'3_Cleaned_Data'!$B:$B,$A18,'3_Cleaned_Data'!$C:$C,D$9) -> 341871.63 | E18: =SUMIFS('3_Cleaned_Data'!$L:$L,'3_Cleaned_Data'!$B:$B,$A18,'3_Cleaned_Data'!$C:$C,E$9) -> 372463.94 | F18: =SUM(B18:E18) -> 1721705.8
A19: Lichtenberg Warehouse | B19: =SUMIFS('3_Cleaned_Data'!$L:$L,'3_Cleaned_Data'!$B:$B,$A19,'3_Cleaned_Data'!$C:$C,B$9) -> 191816.73 | C19: =SUMIFS('3_Cleaned_Data'!$L:$L,'3_Cleaned_Data'!$B:$B,$A19,'3_Cleaned_Data'!$C:$C,C$9) -> 169665.07 | D19: =SUMIFS('3_Cleaned_Data'!$L:$L,'3_Cleaned_Data'!$B:$B,$A19,'3_Cleaned_Data'!$C:$C,D$9) -> 334033.08 | E19: =SUMIFS('3_Cleaned_Data'!$L:$L,'3_Cleaned_Data'!$B:$B,$A19,'3_Cleaned_Data'!$C:$C,E$9) -> 196026.61 | F19: =SUM(B19:E19) -> 891541.49
A20: TOTAL | F20: =SUM(F10:F19) -> 13025727
A23: Contractor | B23: Total Budget | C23: Total Actual | D23: Variance | E23: Variance %
A24: Bauer GmbH | B24: =SUMIF('3_Cleaned_Data'!$D:$D,A24,'3_Cleaned_Data'!$K:$K) -> 1082903.8 | C24: =SUMIF('3_Cleaned_Data'!$D:$D,A24,'3_Cleaned_Data'!$L:$L) -> 1149004.4 | D24: =C24-B24 -> 66100.6 | E24: =D24/B24 -> 0.061040141
A25: STRABAG SE | B25: =SUMIF('3_Cleaned_Data'!$D:$D,A25,'3_Cleaned_Data'!$K:$K) -> 2033764.1 | C25: =SUMIF('3_Cleaned_Data'!$D:$D,A25,'3_Cleaned_Data'!$L:$L) -> 2191020.7 | D25: =C25-B25 -> 157256.6 | E25: =D25/B25 -> 0.077322929
A26: Züblin AG | B26: =SUMIF('3_Cleaned_Data'!$D:$D,A26,'3_Cleaned_Data'!$K:$K) -> 552435.3 | C26: =SUMIF('3_Cleaned_Data'!$D:$D,A26,'3_Cleaned_Data'!$L:$L) -> 532861.74 | D26: =C26-B26 -> -19573.56 | E26: =D26/B26 -> -0.035431407
A27: Max Bögl | B27: =SUMIF('3_Cleaned_Data'!$D:$D,A27,'3_Cleaned_Data'!$K:$K) -> 1585915.1 | C27: =SUMIF('3_Cleaned_Data'!$D:$D,A27,'3_Cleaned_Data'!$L:$L) -> 1521288.1 | D27: =C27-B27 -> -64626.96 | E27: =D27/B27 -> -0.040750581
A28: Goldbeck GmbH | B28: =SUMIF('3_Cleaned_Data'!$D:$D,A28,'3_Cleaned_Data'!$K:$K) -> 1895980.6 | C28: =SUMIF('3_Cleaned_Data'!$D:$D,A28,'3_Cleaned_Data'!$L:$L) -> 1770291.4 | D28: =C28-B28 -> -125689.22 | E28: =D28/B28 -> -0.06629246
A29: Hochtief AG | B29: =SUMIF('3_Cleaned_Data'!$D:$D,A29,'3_Cleaned_Data'!$K:$K) -> 949641.63 | C29: =SUMIF('3_Cleaned_Data'!$D:$D,A29,'3_Cleaned_Data'!$L:$L) -> 851720.4 | D29: =C29-B29 -> -97921.23 | E29: =D29/B29 -> -0.10311388
A30: Ed. Züblin | B30: =SUMIF('3_Cleaned_Data'!$D:$D,A30,'3_Cleaned_Data'!$K:$K) -> 1219328.9 | C30: =SUMIF('3_Cleaned_Data'!$D:$D,A30,'3_Cleaned_Data'!$L:$L) -> 1205408 | D30: =C30-B30 -> -13920.84 | E30: =D30/B30 -> -0.011416805
A31: Implenia DE | B31: =SUMIF('3_Cleaned_Data'!$D:$D,A31,'3_Cleaned_Data'!$K:$K) -> 1026484.1 | C31: =SUMIF('3_Cleaned_Data'!$D:$D,A31,'3_Cleaned_Data'!$L:$L) -> 998108.42 | D31: =C31-B31 -> -28375.63 | E31: =D31/B31 -> -0.027643518
A32: Bilfinger SE | B32: =SUMIF('3_Cleaned_Data'!$D:$D,A32,'3_Cleaned_Data'!$K:$K) -> 1553345.5 | C32: =SUMIF('3_Cleaned_Data'!$D:$D,A32,'3_Cleaned_Data'!$L:$L) -> 1599983.7 | D32: =C32-B32 -> 46638.18 | E32: =D32/B32 -> 0.030024345
A33: Porr GmbH | B33: =SUMIF('3_Cleaned_Data'!$D:$D,A33,'3_Cleaned_Data'!$K:$K) -> 1174648.4 | C33: =SUMIF('3_Cleaned_Data'!$D:$D,A33,'3_Cleaned_Data'!$L:$L) -> 1206039.7 | D33: =C33-B33 -> 31391.3 | E33: =D33/B33 -> 0.026723996
A34: Total | B34: =SUM(B24:B33) -> 13074447 | C34: =SUM(C24:C33) -> 13025727 | D34: =SUM(D24:D33) -> -48720.76 | E34: =D34/B34 -> -0.0037264107

Sheet 5_Budget_vs_Actual
A1: Project Name | B1: Phase | C1: Contractor | D1: Budget | E1: Actual Cost | F1: Variance | G1: Variance % | H1: RAG Status
A2: ='3_Cleaned_Data'!B2 -> Mitte Office Tower | B2: ='3_Cleaned_Data'!C2 -> Foundation | C2: ='3_Cleaned_Data'!D2 -> STRABAG SE | D2: ='3_Cleaned_Data'!K2 -> 124256.53 | E2: ='3_Cleaned_Data'!L2 -> 135508.74 | F2: ='3_Cleaned_Data'!M2 -> 11252.21 | G2: ='3_Cleaned_Data'!N2 -> 0.090556287 | H2: =IF(G2>0.1,"Over Budget",IF(G2>0,"Watch","On Track")) -> Watch
A3: ='3_Cleaned_Data'!B3 -> Friedrichshain Loft | B3: ='3_Cleaned_Data'!C3 -> Structure | C3: ='3_Cleaned_Data'!D3 -> Max Bögl | D3: ='3_Cleaned_Data'!K3 -> 203735.54 | E3: ='3_Cleaned_Data'!L3 -> 195214.39 | F3: ='3_Cleaned_Data'!M3 -> -8521.15 | G3: ='3_Cleaned_Data'!N3 -> -0.041824563 | H3: =IF(G3>0.1,"Over Budget",IF(G3>0,"Watch","On Track")) -> On Track
A4: ='3_Cleaned_Data'!B4 -> Prenzlauer Berg Retail | B4: ='3_Cleaned_Data'!C4 -> Finishing | C4: ='3_Cleaned_Data'!D4 -> Bilfinger SE | D4: ='3_Cleaned_Data'!K4 -> 296824.16 | E4: ='3_Cleaned_Data'!L4 -> 262043.34 | F4: ='3_Cleaned_Data'!M4 -> -34780.82 | G4: ='3_Cleaned_Data'!N4 -> -0.11717651 | H4: =IF(G4>0.1,"Over Budget",IF(G4>0,"Watch","On Track")) -> On Track
A5: ='3_Cleaned_Data'!B5 -> Kreuzberg Residential | B5: ='3_Cleaned_Data'!C5 -> Structure | C5: ='3_Cleaned_Data'!D5 -> Züblin AG | D5: ='3_Cleaned_Data'!K5 -> 228039.86 | E5: ='3_Cleaned_Data'!L5 -> 245179.54 | F5: ='3_Cleaned_Data'!M5 -> 17139.68 | G5: ='3_Cleaned_Data'!N5 -> 0.075160895 | H5: =IF(G5>0.1,"Over Budget",IF(G5>0,"Watch","On Track")) -> Watch
A6: ='3_Cleaned_Data'!B6 -> Kreuzberg Residential | B6: ='3_Cleaned_Data'!C6 -> Mep | C6: ='3_Cleaned_Data'!D6 -> Goldbeck GmbH | D6: ='3_Cleaned_Data'!K6 -> 263606.93 | E6: ='3_Cleaned_Data'!L6 -> 258399.15 | F6: ='3_Cleaned_Data'!M6 -> -5207.78 | G6: ='3_Cleaned_Data'!N6 -> -0.019755854 | H6: =IF(G6>0.1,"Over Budget",IF(G6>0,"Watch","On Track")) -> On Track
A7: ='3_Cleaned_Data'!B7 -> Charlottenburg Hotel | B7: ='3_Cleaned_Data'!C7 -> Finishing | C7: ='3_Cleaned_Data'!D7 -> Bilfinger SE | D7: ='3_Cleaned_Data'!K7 -> 234773.98 | E7: ='3_Cleaned_Data'!L7 -> 227498.98 | F7: ='3_Cleaned_Data'!M7 -> -7275 | G7: ='3_Cleaned_Data'!N7 -> -0.03098725 | H7: =IF(G7>0.1,"Over Budget",IF(G7>0,"Watch","On Track")) -> On Track
A8: ='3_Cleaned_Data'!B8 -> Mitte Office Tower | B8: ='3_Cleaned_Data'!C8 -> Mep | C8: ='3_Cleaned_Data'!D8 -> Hochtief AG | D8: ='3_Cleaned_Data'!K8 -> 523414.42 | E8: ='3_Cleaned_Data'!L8 -> 479256.46 | F8: ='3_Cleaned_Data'!M8 -> -44157.96 | G8: ='3_Cleaned_Data'!N8 -> -0.084365196 | H8: =IF(G8>0.1,"Over Budget",IF(G8>0,"Watch","On Track")) -> On Track
A9: ='3_Cleaned_Data'!B9 -> Spandau Logistics Hub | B9: ='3_Cleaned_Data'!C9 -> Structure | C9: ='3_Cleaned_Data'!D9 -> Ed. Züblin | D9: ='3_Cleaned_Data'!K9 -> 360540.88 | E9: ='3_Cleaned_Data'!L9 -> 423843.31 | F9: ='3_Cleaned_Data'!M9 -> 63302.43 | G9: ='3_Cleaned_Data'!N9 -> 0.17557629 | H9: =IF(G9>0.1,"Over Budget",IF(G9>0,"Watch","On Track")) -> Over Budget
A10: ='3_Cleaned_Data'!B10 -> Wedding School Extension | B10: ='3_Cleaned_Data'!C10 -> Mep | C10: ='3_Cleaned_Data'!D10 -> Goldbeck GmbH | D10: ='3_Cleaned_Data'!K10 -> 418135.98 | E10: ='3_Cleaned_Data'!L10 -> 366252.99 | F10: ='3_Cleaned_Data'!M10 -> -51882.99 | G10: ='3_Cleaned_Data'!N10 -> -0.12408162 | H10: =IF(G10>0.1,"Over Budget",IF(G10>0,"Watch","On Track")) -> On Track
A11: ='3_Cleaned_Data'!B11 -> Lichtenberg Warehouse | B11: ='3_Cleaned_Data'!C11 -> Finishing | C11: ='3_Cleaned_Data'!D11 -> Porr GmbH | D11: ='3_Cleaned_Data'!K11 -> 356054.64 | E11: ='3_Cleaned_Data'!L11 -> 334033.08 | F11: ='3_Cleaned_Data'!M11 -> -22021.56 | G11: ='3_Cleaned_Data'!N11 -> -0.061848822 | H11: =IF(G11>0.1,"Over Budget",IF(G11>0,"Watch","On Track")) -> On Track
A12: ='3_Cleaned_Data'!B12 -> Neukölln Mixed-Use | B12: ='3_Cleaned_Data'!C12 -> Foundation | C12: ='3_Cleaned_Data'!D12 -> STRABAG SE | D12: ='3_Cleaned_Data'!K12 -> 293919.34 | E12: ='3_Cleaned_Data'!L12 -> 337752.87 | F12: ='3_Cleaned_Data'!M12 -> 43833.53 | G12: ='3_Cleaned_Data'!N12 -> 0.14913456 | H12: =IF(G12>0.1,"Over Budget",IF(G12>0,"Watch","On Track")) -> Over Budget
A13: ='3_Cleaned_Data'!B13 -> Charlottenburg Hotel | B13: ='3_Cleaned_Data'!C13 -> Structure | C13: ='3_Cleaned_Data'!D13 -> Goldbeck GmbH | D13: ='3_Cleaned_Data'!K13 -> 208894.01 | E13: ='3_Cleaned_Data'!L13 -> 204756.48 | F13: ='3_Cleaned_Data'!M13 -> -4137.53 | G13: ='3_Cleaned_Data'!N13 -> -0.019806839 | H13: =IF(G13>0.1,"Over Budget",IF(G13>0,"Watch","On Track")) -> On Track
... A41: ='3_Cleaned_Data'!B41 -> Neukölln Mixed-Use | B41: ='3_Cleaned_Data'!C41 -> Finishing | C41: ='3_Cleaned_Data'!D41 -> Ed. Züblin | D41: ='3_Cleaned_Data'!K41 -> 303787.08 | E41: ='3_Cleaned_Data'!L41 -> 273891.54 | F41: ='3_Cleaned_Data'!M41 -> -29895.54 | G41: ='3_Cleaned_Data'!N41 -> -0.098409518 | H41: =IF(G41>0.1,"Over Budget",IF(G41>0,"Watch","On Track")) -> On Track
A44: Total Budget | B44: =SUM(D2:D41) -> 13074447
A45: Total Actual | B45: =SUM(E2:E41) -> 13025727
A46: Total Variance | B46: =SUM(F2:F41) -> -48720.76
A47: Avg Variance % | B47: =AVERAGE(G2:G41) -> -7.6203212e-05
A48: # Over Budget | B48: =COUNTIF(H2:H41,"Over Budget") -> 9
A49: # On Track | B49: =COUNTIF(H2:H41,"On Track") -> 24

Sheet 6_Dashboard
A1: Berlin Construction Cost Tracker
A2: Project Budget & Variance Analysis | Berlin, Germany | 2023-2024
A4: TOTAL BUDGET | C4: TOTAL ACTUAL | E4: TOTAL VARIANCE | G4: AVG VARIANCE % | I4: # OVER BUDGET | K4: # ON TRACK
A5: ='5_Budget_vs_Actual'!B44 -> 13074447 | C5: ='5_Budget_vs_Actual'!B45 -> 13025727 | E5: ='5_Budget_vs_Actual'!B46 -> -48720.76 | G5: ='5_Budget_vs_Actual'!B47 -> -7.6203212e-05 | I5: ='5_Budget_vs_Actual'!B48 -> 9 | K5: ='5_Budget_vs_Actual'!B49 -> 24
A9: COST BY PHASE
A10: Phase | B10: Budget | C10: Actual | D10: Variance | E10: Variance % | F10: Status
A11: Foundation | B11: ='4_Pivot_Analysis'!B2 -> 3321244.3 | C11: ='4_Pivot_Analysis'!C2 -> 3480508.5 | D11: ='4_Pivot_Analysis'!D2 -> 159264.16 | E11: ='4_Pivot_Analysis'!E2 -> 0.04795316 | F11: ='4_Pivot_Analysis'!F2 -> Watch
A12: Structure | B12: ='4_Pivot_Analysis'!B3 -> 3043895.2 | C12: ='4_Pivot_Analysis'!C3 -> 3077031.9 | D12: ='4_Pivot_Analysis'!D3 -> 33136.66 | E12: ='4_Pivot_Analysis'!E3 -> 0.010886268 | F12: ='4_Pivot_Analysis'!F3 -> Watch
A13: Finishing | B13: ='4_Pivot_Analysis'!B4 -> 3158723 | C13: ='4_Pivot_Analysis'!C4 -> 3060874.9 | D13: ='4_Pivot_Analysis'!D4 -> -97848.14 | E13: ='4_Pivot_Analysis'!E4 -> -0.030977119 | F13: ='4_Pivot_Analysis'!F4 -> On Track
A14: Mep | B14: ='4_Pivot_Analysis'!B5 -> 3550584.8 | C14: ='4_Pivot_Analysis'!C5 -> 3407311.4 | D14: ='4_Pivot_Analysis'!D5 -> -143273.44 | E14: ='4_Pivot_Analysis'!E5 -> -0.040352068 | F14: ='4_Pivot_Analysis'!F5 -> On Track
A15: Total | B15: =SUM(B11:B14) -> 13074447 | C15: =SUM(C11:C14) -> 13025727 | D15: =SUM(D11:D14) -> -48720.76 | E15: =D15/B15 -> -0.0037264107
A17: PROJECT VARIANCE SNAPSHOT
A18: Project Name | B18: Total Budget | C18: Total Actual | D18: Variance | E18: Variance % | F18: Rag Status
A19: Mitte Office Tower | B19: =SUMIF('3_Cleaned_Data'!$B:$B,A19,'3_Cleaned_Data'!$K:$K) -> 1280363.5 | C19: =SUMIF('3_Cleaned_Data'!$B:$B,A19,'3_Cleaned_Data'!$L:$L) -> 1251264.4 | D19: =C19-B19 -> -29099.16 | E19: =D19/B19 -> -0.022727264 | F19: =IF(E19>0.1,"Over Budget",IF(E19>0,"Watch","On Track")) -> On Track
A20: Kreuzberg Residential | B20: =SUMIF('3_Cleaned_Data'!$B:$B,A20,'3_Cleaned_Data'!$K:$K) -> 982865.95 | C20: =SUMIF('3_Cleaned_Data'!$B:$B,A20,'3_Cleaned_Data'!$L:$L) -> 950386.28 | D20: =C20-B20 -> -32479.67 | E20: =D20/B20 -> -0.03304588 | F20: =IF(E20>0.1,"Over Budget",IF(E20>0,"Watch","On Track")) -> On Track
A21: Prenzlauer Berg Retail | B21: =SUMIF('3_Cleaned_Data'!$B:$B,A21,'3_Cleaned_Data'!$K:$K) -> 1552431.6 | C21: =SUMIF('3_Cleaned_Data'!$B:$B,A21,'3_Cleaned_Data'!$L:$L) -> 1494627.7 | D21: =C21-B21 -> -57803.87 | E21: =D21/B21 -> -0.037234407 | F21: =IF(E21>0.1,"Over Budget",IF(E21>0,"Watch","On Track")) -> On Track
A22: Charlottenburg Hotel | B22: =SUMIF('3_Cleaned_Data'!$B:$B,A22,'3_Cleaned_Data'!$K:$K) -> 1071156.4 | C22: =SUMIF('3_Cleaned_Data'!$B:$B,A22,'3_Cleaned_Data'!$L:$L) -> 1117057.3 | D22: =C22-B22 -> 45900.83 | E22: =D22/B22 -> 0.042851659 | F22: =IF(E22>0.1,"Over Budget",IF(E22>0,"Watch","On Track")) -> Watch
A23: Neukölln Mixed-Use | B23: =SUMIF('3_Cleaned_Data'!$B:$B,A23,'3_Cleaned_Data'!$K:$K) -> 1246852.1 | C23: =SUMIF('3_Cleaned_Data'!$B:$B,A23,'3_Cleaned_Data'!$L:$L) -> 1241571.3 | D23: =C23-B23 -> -5280.77 | E23: =D23/B23 -> -0.0042352818 | F23: =IF(E23>0.1,"Over Budget",IF(E23>0,"Watch","On Track")) -> On Track
A24: Spandau Logistics Hub | B24: =SUMIF('3_Cleaned_Data'!$B:$B,A24,'3_Cleaned_Data'!$K:$K) -> 1339681.7 | C24: =SUMIF('3_Cleaned_Data'!$B:$B,A24,'3_Cleaned_Data'!$L:$L) -> 1500690.1 | D24: =C24-B24 -> 161008.39 | E24: =D24/B24 -> 0.12018406 | F24: =IF(E24>0.1,"Over Budget",IF(E24>0,"Watch","On Track")) -> Over Budget
A25: Friedrichshain Loft | B25: =SUMIF('3_Cleaned_Data'!$B:$B,A25,'3_Cleaned_Data'!$K:$K) -> 1520502.9 | C25: =SUMIF('3_Cleaned_Data'!$B:$B,A25,'3_Cleaned_Data'!$L:$L) -> 1517707.1 | D25: =C25-B25 -> -2795.77 | E25: =D25/B25 -> -0.001838714 | F25: =IF(E25>0.1,"Over Budget",IF(E25>0,"Watch","On Track")) -> On Track
A26: Wedding School Extension | B26: =SUMIF('3_Cleaned_Data'!$B:$B,A26,'3_Cleaned_Data'!$K:$K) -> 1305552.8 | C26: =SUMIF('3_Cleaned_Data'!$B:$B,A26,'3_Cleaned_Data'!$L:$L) -> 1339175.1 | D26: =C26-B26 -> 33622.26 | E26: =D26/B26 -> 0.025753274 | F26: =IF(E26>0.1,"Over Budget",IF(E26>0,"Watch","On Track")) -> Watch
A27: Steglitz Medical Centre | B27: =SUMIF('3_Cleaned_Data'!$B:$B,A27,'3_Cleaned_Data'!$K:$K) -> 1821414.7 | C27: =SUMIF('3_Cleaned_Data'!$B:$B,A27,'3_Cleaned_Data'!$L:$L) -> 1721705.8 | D27: =C27-B27 -> -99708.97 | E27: =D27/B27 -> -0.054742596 | F27: =IF(E27>0.1,"Over Budget",IF(E27>0,"Watch","On Track")) -> On Track
A28: Lichtenberg Warehouse | B28: =SUMIF('3_Cleaned_Data'!$B:$B,A28,'3_Cleaned_Data'!$K:$K) -> 953625.52 | C28: =SUMIF('3_Cleaned_Data'!$B:$B,A28,'3_Cleaned_Data'!$L:$L) -> 891541.49 | D28: =C28-B28 -> -62084.03 | E28: =D28/B28 -> -0.065103155 | F28: =IF(E28>0.1,"Over Budget",IF(E28>0,"Watch","On Track")) -> On Track
A30: Note: | B30: Red = over 10% over budget
B31: Yellow = 0-10% over
B32: Green = on or under budget
